Workbook

Sheet Таблица полная Grt
A1: № образца | B1: порода | C1: №анализа EPMA | D1: SiO2 | E1: кружок | F1: точка_SIMS | G1: SiO2 | H1: TiO2 | I1: Al2O3 | J1: Cr2O3 | K1: FeO | L1: MgO | M1: MnO | N1: CaO | O1: NiO | P1: Na2O | Q1: K2O | R1: SrO | S1: BaO | T1: P2O5 | U1: F | V1: S | W1: Zr | X1: Nb | Y1: Y | Z1: V | AA1: W | AB1: Cl | AC1: Total | AD1: 085Rb | AE1: 087Rb_str | AF1: 088Sr | AG1: 090Zr | AH1: 140Ce | AI1: 149Sm | AJ1: 158Gd | AK1: 167Er | AL1: 174Yb | AM1: 178Hf | AN1: 232Th | AO1: 238U | AP1: 181Ta | AQ1: 165Ho | AR1: 163Dy | AS1: 153Eu | AT1: 143Nd | AU1: 139La | AV1: 093Nb | AW1: 089Y | AX1: 051V | AY1: 047Ti | AZ1: 011B | BA1: 007Li | BB1: 158Gd str | BC1: 174Yb str | BD1: 153Eu str | BE1: 167Er str | BF1: delta Ti | BG1: delta Zr | BH1: % (Zr) | BI1: delta V | BJ1: % (V) | BK1: Sm/Ybn | BL1: Sm/Lan | BM1: Y/Ho | BN1: La/Ybn | BO1: Nb/Ta
A2: 19ТР-14 | C2: 15 | D2: 35.86 | E2: 10 | F2: 56 | G2: 35.86 | H2: 0.66 | I2: 5.09 | J2: 0 | K2: 20.02 | L2: 0.67 | M2: 0.45 | N2: 33.37 | P2: 0.08 | AC2: 96.32 | AD2: 120.54018 | AE2: 41.048473 | AF2: 6011.1496 | AG2: 733.82623 | AH2: 1781.6996 | AI2: 45.304599 | AJ2: 450.24065 | AK2: 10.102139 | AL2: 16.087784 | AM2: 9.9514345 | AN2: 33.439829 | AO2: 30.845801 | AP2: 8.5992775 | AQ2: 3.064566 | AR2: 16.599864 | AS2: 20.104094 | AT2: 476.37131 | AU2: 1034.0432 | AV2: 344.44166 | AW2: 67.425013 | AX2: 605.18692 | AY2: 6393.1943 | AZ2: 22.772075 | BA2: 31.182327 | BB2: 54.955625 | BC2: 3.5079491 | BD2: 11.094916 | BE2: 7.8238434 | BF2: =H2*5993.43-AY2 -> -2437.5305 | BK2: ='для графера'!F28/'для графера'!N28 -> 14.349821 | BL2: ='для графера'!F28/'для графера'!B28 -> 0.067867291 | BM2: =AW2/AQ2 -> 22.001488 | BN2: ='для графера'!B28/'для графера'!N28 -> 211.43943 | BO2: =AV2/AP2 -> 40.054721
A3: 19ТР-14 | C3: 16 | D3: 35.76 | E3: 10 | F3: 57 | G3: 35.76 | H3: 1.13 | I3: 5.21 | J3: 0 | K3: 19.41 | L3: 0.76 | M3: 0.36 | N3: 33.28 | P3: 0 | AC3: 96.07 | AD3: 248.67829 | AE3: 234.55855 | AF3: 1158.1435 | AG3: 347.85326 | AH3: 596.78776 | AI3: 38.624637 | AJ3: 159.15416 | AK3: 7.0714723 | AL3: 8.9077377 | AM3: 6.5084448 | AN3: 29.67671 | AO3: 7.2611026 | AP3: 8.4415199 | AQ3: 2.5745193 | AR3: 12.988554 | AS3: 26.308437 | AT3: 278.86423 | AU3: 245.31857 | AV3: 253.57488 | AW3: 43.156379 | AX3: 334.29366 | AY3: 5839.1291 | AZ3: 18.009009 | BA3: 30.284712 | BB3: 24.219737 | BC3: 4.4451114 | BD3: 10.390675 | BE3: 4.9377903 | BF3: =H3*5993.43-AY3 -> 933.44678 | BK3: ='для графера'!F29/'для графера'!N29 -> 9.6547105 | BL3: ='для графера'!F29/'для графера'!B29 -> 0.24388827 | BM3: =AW3/AQ3 -> 16.762888 | BN3: ='для графера'!B29/'для графера'!N29 -> 39.586613 | BO3: =AV3/AP3 -> 30.039008
A4: 19ТР-14 | C4: 20 | D4: 30.33 | E4: 10 | F4: 58 | G4: 30.33 | H4: 10.51 | I4: 2.78 | J4: 0 | K4: 19.88 | L4: 1.02 | M4: 0.13 | N4: 32.6 | P4: 0.14 | AC4: 97.49 | AD4: 26.367988 | AE4: -74.940222 | AF4: 1892.0579 | AG4: 1058.8892 | AH4: 233.62538 | AI4: 40.419738 | AJ4: 121.08612 | AK4: 12.282063 | AL4: 14.493058 | AM4: 28.721554 | AN4: 13.856181 | AO4: 2.1506082 | AP4: 9.08357 | AQ4: 3.7600849 | AR4: 20.632013 | AS4: 12.880892 | AT4: 175.72799 | AU4: 73.50371 | AV4: 269.07941 | AW4: 68.356805 | AX4: 154.85835 | AY4: 44211.343 | AZ4: 9.6612716 | BA4: 7.1549451 | BB4: 33.449854 | BC4: 5.9405549 | BD4: 11.377122 | BE4: 9.9458186 | BF4: =H4*5993.43-AY4 -> 18779.606 | BK4: ='для графера'!F30/'для графера'!N30 -> 7.5600379 | BL4: ='для графера'!F30/'для графера'!B30 -> 0.85180689 | BM4: =AW4/AQ4 -> 18.179591 | BN4: ='для графера'!B30/'для графера'!N30 -> 8.8752956 | BO4: =AV4/AP4 -> 29.62265
A5: 19ТР-14 | C5: 21 | D5: 36.24 | E5: 10 | F5: 59 | G5: 36.24 | H5: 0.74 | I5: 6.18 | J5: 0 | K5: 19.34 | L5: 0.49 | M5: 0.15 | N5: 34.07 | P5: 0 | AC5: 97.29 | AD5: 72.349975 | AE5: 53.66466 | AF5: 900.24921 | AG5: 158.05262 | AH5: 419.29094 | AI5: 30.735235 | AJ5: 136.17183 | AK5: 5.1885101 | AL5: 5.0617672 | AM5: 4.1268597 | AN5: 19.820978 | AO5: 5.8725745 | AP5: 12.536784 | AQ5: 1.7153426 | AR5: 9.577458 | AS5: 8.2284188 | AT5: 250.70072 | AU5: 119.25221 | AV5: 1116.6029 | AW5: 24.409094 | AX5: 328.37991 | AY5: 10524.167 | AZ5: 13.236568 | BA5: 9.7623404 | BB5: 17.747186 | BC5: 1.4955916 | BD5: 6.9827542 | BE5: 3.7546305 | BF5: =H5*5993.43-AY5 -> -6089.029 | BK5: ='для графера'!F31/'для графера'!N31 -> 22.833949 | BL5: ='для графера'!F31/'для графера'!B31 -> 0.39923353 | BM5: =AW5/AQ5 -> 14.229865 | BN5: ='для графера'!B31/'для графера'!N31 -> 57.194466 | BO5: =AV5/AP5 -> 89.066136
A6: 18КЛ-20 | C6: 26 | D6: 28.03 | E6: 15 | F6: 60 | G6: 28.03 | H6: 16.25 | I6: 0.72 | K6: 16.21 | L6: 1.07 | M6: 0.51 | N6: 30.03 | P6: 0.86 | W6: 2.5 | X6: 1.3 | Z6: 0.35 | AC6: 97.84 | AD6: 16.101494 | AE6: 7.566526 | AF6: 301.56437 | AG6: 16400.555 | AH6: 278.01964 | AI6: 107.00869 | AJ6: 220.63405 | AK6: 164.10925 | AL6: 166.40044 | AM6: 232.47849 | AN6: 9.6226065 | AO6: 56.166388 | AP6: 37.71894 | AQ6: 45.975457 | AR6: 202.14862 | AS6: 42.267737 | AT6: 226.77415 | AU6: 110.41768 | AV6: 11813.969 | AW6: 1142.2974 | AX6: 1199.6323 | AY6: 127669.85 | AZ6: 6.3724175 | BA6: 34.350574 | BB6: 130.54156 | BC6: 139.92229 | BD6: 43.214541 | BE6: 155.23532 | BF6: =H6*5993.43-AY6 -> -30276.61 | BG6: =W6*8701-AG6 -> 5351.9447 | BH6: =(BG6/AG6)*100 -> 32.632704 | BI6: =6797*Z6 - AX6 -> 1179.3177 | BJ6: =BI6/AX6*100 -> 98.306601 | BK6: ='для графера'!F32/'для графера'!N32 -> 0.84974698 | BL6: ='для графера'!F32/'для графера'!B32 -> 1.5011958 | BM6: =AW6/AQ6 -> 24.845808 | BN6: ='для графера'!B32/'для графера'!N32 -> 0.56604672 | BO6: =AV6/AP6 -> 313.21052
A7: 18КЛ-20 | C7: 27 | D7: 29.99 | E7: 15 | F7: 61 | G7: 29.99 | H7: 12.85 | I7: 1.32 | K7: 17.94 | L7: 1.04 | M7: 0.33 | N7: 31.91 | P7: 0.34 | W7: 0.76 | X7: 0.23 | Z7: 0.42 | AC7: 97.42 | AD7: 11.871125 | AE7: 1.6750625 | AF7: 164.13157 | AG7: 5425.05 | AH7: 462.66892 | AI7: 88.850839 | AJ7: 202.21551 | AK7: 33.786477 | AL7: 37.964867 | AM7: 73.425534 | AN7: 25.271338 | AO7: 49.371659 | AP7: 15.079262 | AQ7: 10.310295 | AR7: 52.944556 | AS7: 25.931482 | AT7: 431.0176 | AU7: 119.88284 | AV7: 2221.1471 | AW7: 277.23583 | AX7: 1271.6459 | AY7: 75171.357 | AZ7: 18.682465 | BA7: 29.526228 | BB7: 64.999971 | BC7: 25.399656 | BD7: 25.776979 | BE7: 28.493281 | BF7: =H7*5993.43-AY7 -> 1844.2181 | BG7: =W7*8701-AG7 -> 1187.71 | BH7: =(BG7/AG7)*100 -> 21.89307 | BI7: =6797*Z7 - AX7 -> 1583.0941 | BJ7: =BI7/AX7*100 -> 124.49175 | BK7: ='для графера'!F33/'для графера'!N33 -> 3.8867911 | BL7: ='для графера'!F33/'для графера'!B33 -> 1.1480517 | BM7: =AW7/AQ7 -> 26.889224 | BN7: ='для графера'!B33/'для графера'!N33 -> 3.3855541 | BO7: =AV7/AP7 -> 147.29813
A8: 18КЛ-20 | C8: 28 | D8: 34.97 | E8: 15 | F8: 62 | G8: 34.97 | H8: 2.97 | I8: 3.39 | K8: 20.97 | L8: 0.71 | M8: 0.33 | N8: 32.85 | P8: 0.11 | W8: 0 | X8: 0 | Z8: 0.66 | AC8: 96.97 | AD8: 17.719353 | AE8: 2.4413274 | AF8: 186.63152 | AG8: 3931.3465 | AH8: 484.68148 | AI8: 85.743796 | AJ8: 198.34458 | AK8: 38.654545 | AL8: 40.659238 | AM8: 63.500843 | AN8: 30.966825 | AO8: 44.753145 | AP8: 11.802762 | AQ8: 11.340021 | AR8: 54.334172 | AS8: 24.296879 | AT8: 434.37781 | AU8: 112.27071 | AV8: 2613.7389 | AW8: 295.27207 | AX8: 2149.124 | AY8: 57652.051 | AZ8: 11.023345 | BA8: 22.9557 | BB8: 63.023772 | BC8: 29.651319 | BD8: 24.524151 | BE8: 33.618613 | BF8: =H8*5993.43-AY8 -> -39851.564 | BI8: =6797*Z8 - AX8 -> 2336.896 | BJ8: =BI8/AX8*100 -> 108.73715 | BK8: ='для графера'!F34/'для графера'!N34 -> 3.2130403 | BL8: ='для графера'!F34/'для графера'!B34 -> 1.1830229 | BM8: =AW8/AQ8 -> 26.038054 | BN8: ='для графера'!B34/'для графера'!N34 -> 2.7159579 | BO8: =AV8/AP8 -> 221.45147
A9: 18КЛ-20 | C9: 32 | D9: 29.78 | E9: 16 | F9: 63 | G9: 29.78 | H9: 13.74 | I9: 1.38 | K9: 17.55 | L9: 0.98 | M9: 0.31 | N9: 32.01 | P9: 0.27 | W9: 0 | X9: 0.37 | Z9: 0.46 | AC9: 97.31 | AD9: 16.567441 | AE9: 4.2619958 | AF9: 219.65719 | AG9: 1944.0573 | AH9: 566.86529 | AI9: 108.79519 | AJ9: 249.56455 | AK9: 27.683762 | AL9: 30.034818 | AM9: 33.638991 | AN9: 48.051684 | AO9: 51.566184 | AP9: 33.644576 | AQ9: 8.8715454 | AR9: 47.439473 | AS9: 30.454177 | AT9: 533.37701 | AU9: 128.84464 | AV9: 3015.6365 | AW9: 204.74148 | AX9: 1306.1137 | AY9: 93455.517 | AZ9: 6.5160791 | BA9: 25.177641 | BB9: 65.263657 | BC9: 17.344705 | BD9: 30.423668 | BE9: 21.436387 | BF9: =H9*5993.43-AY9 -> -11105.788 | BI9: =6797*Z9 - AX9 -> 1820.5063 | BJ9: =BI9/AX9*100 -> 139.38346 | BK9: ='для графера'!F35/'для графера'!N35 -> 6.969478 | BL9: ='для графера'!F35/'для графера'!B35 -> 1.3079774 | BM9: =AW9/AQ9 -> 23.078445 | BN9: ='для графера'!B35/'для графера'!N35 -> 5.328439 | BO9: =AV9/AP9 -> 89.632175
A10: 18КЛ-20 | C10: 33 | D10: 30.07 | E10: 16 | F10: 64 | G10: 30.07 | H10: 12.53 | I10: 1.34 | K10: 17.76 | L10: 0.94 | M10: 0.34 | N10: 31.92 | P10: 0.34 | W10: 0 | X10: 0.26 | Z10: 0.45 | AC10: 95.96 | AD10: 19.993018 | AE10: 4.74881 | AF10: 166.08952 | AG10: 1958.3457 | AH10: 785.60467 | AI10: 124.46545 | AJ10: 311.64513 | AK10: 48.567094 | AL10: 49.218413 | AM10: 37.428371 | AN10: 67.444505 | AO10: 69.987683 | AP10: 45.02241 | AQ10: 14.196713 | AR10: 69.634282 | AS10: 32.611769 | AT10: 651.27022 | AU10: 177.5212 | AV10: 7070.5663 | AW10: 335.36849 | AX10: 1845.6146 | AY10: 120975.59 | AZ10: 6.8655278 | BA10: 41.210307 | BB10: 68.982309 | BC10: 36.235466 | BD10: 32.414096 | BE10: 41.910994 | BF10: =H10*5993.43-AY10 -> -45877.913 | BI10: =6797*Z10 - AX10 -> 1213.0354 | BJ10: =BI10/AX10*100 -> 65.725282 | BK10: ='для графера'!F36/'для графера'!N36 -> 3.8165632 | BL10: ='для графера'!F36/'для графера'!B36 -> 1.0860643 | BM10: =AW10/AQ10 -> 23.622967 | BN10: ='для графера'!B36/'для графера'!N36 -> 3.5141229 | BO10: =AV10/AP10 -> 157.04549
A11: 19ТР-9 | C11: 44 | D11: 33.64 | E11: 17 | F11: 65 | G11: 33.64 | H11: 7.45 | I11: 2.28 | K11: 19.15 | L11: 0 | M11: 0.18 | N11: 33.27 | P11: 0.19 | AC11: 97.23 | AD11: 25.600275 | AE11: -11.980122 | AF11: 602.93746 | AG11: 194.38244 | AH11: 168.53461 | AI11: 11.092044 | AJ11: 51.878465 | AK11: 3.2992515 | AL11: 3.2050887 | AM11: 5.1570469 | AN11: 8.2131271 | AO11: 1.7834475 | AP11: 3.5139397 | AQ11: 1.0660738 | AR11: 5.5091964 | AS11: 3.0509331 | AT11: 86.468565 | AU11: 66.154722 | AV11: 275.7145 | AW11: 30.136638 | AX11: 1051.2632 | AY11: 67693.958 | AZ11: 3.7911879 | BA11: 32.453493 | BB11: 8.8532852 | BC11: 1.3616188 | BD11: 2.9045034 | BE11: 2.7028238 | BF11: =H11*5993.43-AY11 -> -23042.905 | BI11: =6797*Z11 - AX11 -> -1051.2632 | BJ11: =BI11/AX11*100 -> -100 | BK11: ='для графера'!F37/'для графера'!N37 -> 9.0513542 | BL11: ='для графера'!F37/'для графера'!B37 -> 0.25972136 | BM11: =AW11/AQ11 -> 28.268811 | BN11: ='для графера'!B37/'для графера'!N37 -> 34.850249 | BO11: =AV11/AP11 -> 78.46307
A12: 19ТР-9 | C12: 45 | D12: 35.58 | E12: 17 | F12: 66 | G12: 35.58 | H12: 1.62 | I12: 2.52 | K12: 23.08 | L12: 0.17 | M12: 0.07 | N12: 32.94 | P12: 0.09 | AC12: 97.33 | AD12: 120.67089 | AE12: 97.974972 | AF12: 816.27666 | AG12: 58.95899 | AH12: 152.16439 | AI12: 8.9608948 | AJ12: 39.111367 | AK12: 3.739763 | AL12: 3.3102606 | AM12: 2.7292877 | AN12: 10.315903 | AO12: 1.4674208 | AP12: 2.4100091 | AQ12: 0.99705084 | AR12: 4.8853062 | AS12: 4.2683776 | AT12: 68.285755 | AU12: 79.83491 | AV12: 133.12032 | AW12: 25.899123 | AX12: 418.53212 | AY12: 9877.7362 | AZ12: 17.763153 | BA12: 11.869815 | BB12: 5.8044676 | BC12: 2.2049916 | BD12: 2.2695313 | BE12: 3.2737241 | BF12: =H12*5993.43-AY12 -> -168.37963 | BI12: =6797*Z12 - AX12 -> -418.53212 | BJ12: =BI12/AX12*100 -> -100 | BK12: ='для графера'!F38/'для графера'!N38 -> 4.5154592 | BL12: ='для графера'!F38/'для графера'!B38 -> 0.17386632 | BM12: =AW12/AQ12 -> 25.97573 | BN12: ='для графера'!B38/'для графера'!N38 -> 25.970868 | BO12: =AV12/AP12 -> 55.236442
A13: 19ТР-12 | C13: 15 | D13: 28.21 | E13: 18 | F13: 67 | G13: 28.21 | H13: 14.97 | I13: 2.29 | K13: 19.74 | M13: 0.39 | N13: 31.74 | P13: 0.18 | W13: 0 | Z13: 0.29 | AC13: 98.91 | AD13: 11.627278 | AE13: 3.446909 | AF13: 500.18369 | AG13: 1272.3555 | AH13: 422.2581 | AI13: 69.428906 | AJ13: 165.19086 | AK13: 15.875358 | AL13: 15.013055 | AM13: 31.533989 | AN13: 19.857099 | AO13: 7.7801906 | AP13: 18.564142 | AQ13: 5.4273051 | AR13: 30.615247 | AS13: 19.428172 | AT13: 391.58211 | AU13: 86.945288 | AV13: 567.37414 | AW13: 112.37979 | AX13: 899.61967 | AY13: 75529.288 | AZ13: 5.3276993 | BA13: 27.242898 | BB13: 44.003416 | BC13: 7.4592621 | BD13: 18.785499 | BE13: 12.017833 | BF13: =H13*5993.43-AY13 -> 14192.359 | BI13: =6797*Z13 - AX13 -> 1071.5103 | BJ13: =BI13/AX13*100 -> 119.10704 | BK13: ='для графера'!F39/'для графера'!N39 -> 10.341938 | BL13: ='для графера'!F39/'для графера'!B39 -> 1.2369473 | BM13: =AW13/AQ13 -> 20.70637 | BN13: ='для графера'!B39/'для графера'!N39 -> 8.3608563 | BO13: =AV13/AP13 -> 30.562907
A14: 19ТР-12 | C14: 17 | D14: 29.01 | E14: 18 | F14: 68 | G14: 29.01 | H14: 13.38 | I14: 2.31 | K14: 20.38 | M14: 0.39 | N14: 31.89 | P14: 0.19 | W14: 0.21 | Z14: 0.31 | AC14: 99.13 | AD14: 19.738275 | AE14: 10.926493 | AF14: 795.8279 | AG14: 496.65317 | AH14: 80.559283 | AI14: 13.09262 | AJ14: 34.03186 | AK14: 3.2789355 | AL14: 3.3506098 | AM14: 11.613744 | AN14: 2.5772759 | AO14: 1.1903946 | AP14: 2.7373581 | AQ14: 0.94728371 | AR14: 4.9551234 | AS14: 3.5172637 | AT14: 74.691446 | AU14: 22.979261 | AV14: 90.632215 | AW14: 21.043958 | AX14: 185.01329 | AY14: 14970.99 | AZ14: 5.4972745 | BA14: 13.450927 | BB14: 7.5139897 | BC14: 1.5352522 | BD14: 3.5190589 | BE14: 2.5563113 | BF14: =H14*5993.43-AY14 -> 65221.103 | BG14: =W14*8701-AG14 -> 1330.5568 | BH14: =BG14/AG14*100 -> 267.90463 | BI14: =6797*Z14 - AX14 -> 1922.0567 | BJ14: =BI14/AX14*100 -> 1038.8749 | BK14: ='для графера'!F40/'для графера'!N40 -> 9.475548 | BL14: ='для графера'!F40/'для графера'!B40 -> 0.88256645 | BM14: =AW14/AQ14 -> 22.215053 | BN14: ='для графера'!B40/'для графера'!N40 -> 10.736356 | BO14: =AV14/AP14 -> 33.109374
A15: 19ТР-18 | C15: 1 | D15: 33.3 | E15: 19 | F15: 69 | G15: 33.3 | H15: 8.53 | I15: 1.3 | K15: 20.68 | L15: 0.55 | M15: 0.51 | N15: 32.07 | P15: 0.5 | W15: 0 | X15: 0.23 | AC15: 97.68 | AD15: 25.211637 | AE15: 3.4268815 | AF15: 250.0105 | AG15: 4673.9027 | AH15: 309.91077 | AI15: 50.105502 | AJ15: 129.87821 | AK15: 38.620265 | AL15: 47.204907 | AM15: 85.43662 | AN15: 5.9448778 | AO15: 8.5338082 | AP15: 21.591096 | AQ15: 11.057827 | AR15: 54.477679 | AS15: 17.552605 | AT15: 209.81589 | AU15: 125.31861 | AV15: 3146.9932 | AW15: 338.06472 | AX15: 3037.1376 | AY15: 92815.658 | AZ15: 9.8273925 | BA15: 141.62801 | BB15: 44.286034 | BC15: 38.244047 | BD15: 17.324153 | BE15: 35.062822 | BF15: =H15*5993.43-AY15 -> -41691.7 | BK15: ='для графера'!F41/'для графера'!N41 -> 1.4557241 | BL15: ='для графера'!F41/'для графера'!B41 -> 0.61933664 | BM15: =AW15/AQ15 -> 30.572437 | BN15: ='для графера'!B41/'для графера'!N41 -> 2.3504569 | BO15: =AV15/AP15 -> 145.75421
A16: 19ТР-18 | C16: 3 | D16: 34.63 | E16: 19 | F16: 70 | G16: 34.63 | H16: 2.52 | I16: 0.62 | K16: 25.55 | L16: 0.06 | M16: 0.42 | N16: 32.49 | P16: 0.19 | W16: 0 | X16: 0 | AC16: 96.51 | AD16: 33.317293 | AE16: -12.417014 | AF16: 159.87472 | AG16: 696.98624 | AH16: 42.910361 | AI16: 8.4448085 | AJ16: 18.913392 | AK16: 4.7579841 | AL16: 4.6504863 | AM16: 13.598604 | AN16: 2.9711835 | AO16: 1.1871599 | AP16: 1.22963 | AQ16: 1.5960987 | AR16: 7.325058 | AS16: 2.8550013 | AT16: 35.287657 | AU16: 12.940779 | AV16: 214.44473 | AW16: 37.542993 | AX16: 2264.2389 | AY16: 24008.896 | AZ16: 4.2781321 | BA16: 67.097933 | BB16: 8.9852694 | BC16: 3.546061 | BD16: 2.711202 | BE16: 4.20125 | BF16: =H16*5993.43-AY16 -> -8905.4522 | BK16: ='для графера'!F42/'для графера'!N42 -> 2.6460686 | BL16: ='для графера'!F42/'для графера'!B42 -> 1.010849 | BM16: =AW16/AQ16 -> 23.521723 | BN16: ='для графера'!B42/'для графера'!N42 -> 2.6176694 | BO16: =AV16/AP16 -> 174.39777
A17: 19ТР-18 | C17: 11 | D17: 28.37 | E17: 20 | F17: 71 | G17: 28.37 | H17: 17.48 | I17: 0.78 | K17: 17.73 | L17: 1.09 | M17: 0.41 | N17: 31.13 | P17: 0.47 | W17: 0.52 | X17: 0.44 | AC17: 98.41 | AD17: 16.828483 | AE17: -7.8980637 | AF17: 354.36418 | AG17: 8252.0044 | AH17: 514.39341 | AI17: 109.17764 | AJ17: 257.81043 | AK17: 70.249815 | AL17: 72.01768 | AM17: 118.24257 | AN17: 16.40806 | AO17: 12.592618 | AP17: 43.093545 | AQ17: 20.609464 | AR17: 97.341864 | AS17: 35.71683 | AT17: 386.36411 | AU17: 170.50923 | AV17: 4643.1749 | AW17: 541.50899 | AX17: 653.36166 | AY17: 155343.37 | AZ17: 8.95481 | BA17: 38.157365 | BB17: 116.53616 | BC17: 48.694135 | BD17: 36.098421 | BE17: 62.837154 | BF17: =H17*5993.43-AY17 -> -50578.212 | BG17: =W17*8701-AG17 -> -3727.4844 | BH17: =BG17/AG17*100 -> -45.170655 | BK17: ='для графера'!F43/'для графера'!N43 -> 2.4912341 | BL17: ='для графера'!F43/'для графера'!B43 -> 0.99184254 | BM17: =AW17/AQ17 -> 26.274773 | BN17: ='для графера'!B43/'для графера'!N43 -> 2.5117234 | BO17: =AV17/AP17 -> 107.74641
A18: 19ТР-18 | C18: 12 | D18: 27.19 | E18: 20 | F18: 72 | G18: 27.19 | H18: 18.58 | I18: 0.97 | K18: 17.07 | L18: 1.32 | M18: 0.37 | N18: 31.21 | P18: 0.39 | W18: 0.76 | X18: 0.29 | AC18: 98.16 | AD18: 17.499474 | AE18: 7.7176914 | AF18: 353.49798 | AG18: 8953.2926 | AH18: 482.81437 | AI18: 126.7816 | AJ18: 281.8801 | AK18: 96.315236 | AL18: 104.76118 | AM18: 168.1849 | AN18: 11.453377 | AO18: 10.346472 | AP18: 45.339978 | AQ18: 29.540593 | AR18: 143.08909 | AS18: 47.37855 | AT18: 417.00786 | AU18: 158.46151 | AV18: 3137.9957 | AW18: 768.04133 | AX18: 590.70417 | AY18: 161983.12 | AZ18: 10.16289 | BA18: 30.833656 | BB18: 130.22321 | BC18: 78.436418 | BD18: 47.26516 | BE18: 86.609531 | BF18: =H18*5993.43-AY18 -> -50625.193 | BG18: =W18*8701-AG18 -> -2340.5326 | BH18: =BG18/AG18*100 -> -26.141585 | BK18: ='для графера'!F44/'для графера'!N44 -> 1.7959571 | BL18: ='для графера'!F44/'для графера'!B44 -> 1.2393367 | BM18: =AW18/AQ18 -> 25.999523 | BN18: ='для графера'!B44/'для графера'!N44 -> 1.4491276 | BO18: =AV18/AP18 -> 69.210349
A19: 19ТР-18 | C19: 13 | D19: 30.62 | E19: 20 | F19: 73 | G19: 30.62 | H19: 13.38 | I19: 0.79 | K19: 18.86 | L19: 0.77 | M19: 0.4 | N19: 32.63 | P19: 0.46 | W19: 0.52 | X19: 0.4 | AC19: 98.83 | AD19: 22.906804 | AE19: -360.75597 | AF19: 12160.476 | AG19: 7061.1784 | AH19: 584.04861 | AI19: 80.434363 | AJ19: 220.71931 | AK19: 58.268804 | AL19: 72.883443 | AM19: 133.17051 | AN19: 7.9918879 | AO19: 19.130986 | AP19: 25.282921 | AQ19: 16.950913 | AR19: 81.493515 | AS19: 37.891985 | AT19: 291.54754 | AU19: 350.47007 | AV19: 4707.2347 | AW19: 485.49916 | AX19: 3430.6765 | AY19: 156306.31 | AZ19: 23.091757 | BA19: 78.11808 | BB19: 75.680526 | BC19: 56.248096 | BD19: 28.595386 | BE19: 52.39686 | BF19: =H19*5993.43-AY19 -> -76114.219 | BG19: =W19*8701-AG19 -> -2536.6584 | BH19: =BG19/AG19*100 -> -35.92401 | BK19: ='для графера'!F45/'для графера'!N45 -> 1.5888807 | BL19: ='для графера'!F45/'для графера'!B45 -> 0.35550655 | BM19: =AW19/AQ19 -> 28.641476 | BN19: ='для графера'!B45/'для графера'!N45 -> 4.469343 | BO19: =AV19/AP19 -> 186.18239
A20: 19ТР-18 | C20: 14 | D20: 34.92 | E20: 20 | F20: 74 | G20: 34.92 | H20: 3.15 | I20: 2.17 | K20: 22.62 | L20: 0.47 | M20: 0.4 | N20: 32.29 | P20: 0.3 | W20: 0 | X20: 0 | AC20: 96.38 | AD20: 69.045192 | AE20: 37.715278 | AF20: 271.99034 | AG20: 2203.068 | AH20: 175.24994 | AI20: 32.299503 | AJ20: 79.285201 | AK20: 22.297901 | AL20: 27.379215 | AM20: 41.44299 | AN20: 3.5509362 | AO20: 4.3589131 | AP20: 5.9605493 | AQ20: 6.2820708 | AR20: 30.827835 | AS20: 11.422916 | AT20: 127.71344 | AU20: 65.668437 | AV20: 1073.9874 | AW20: 205.20932 | AX20: 2580.0442 | AY20: 28635.597 | AZ20: 21.042483 | BA20: 47.332086 | BB20: 30.165667 | BC20: 21.292759 | BD20: 10.300473 | BE20: 20.182742 | BF20: =H20*5993.43-AY20 -> -9756.2924 | BK20: ='для графера'!F46/'для графера'!N46 -> 1.6854714 | BL20: ='для графера'!F46/'для графера'!B46 -> 0.76189666 | BM20: =AW20/AQ20 -> 32.665872 | BN20: ='для графера'!B46/'для графера'!N46 -> 2.2122047 | BO20: =AV20/AP20 -> 180.18262
A21: 19ТР-18 | C21: 16 | D21: 28.28 | E21: 21 | F21: 75 | G21: 28.28 | H21: 17.24 | I21: 0.76 | K21: 17.8 | L21: 1.14 | M21: 0.41 | N21: 31.15 | P21: 0.47 | W21: 0.59 | X21: 0.48 | AC21: 98.3 | AD21: 21.145436 | AE21: 13.22042 | AF21: 401.76143 | AG21: 6770.9198 | AH21: 387.62676 | AI21: 95.506861 | AJ21: 214.83012 | AK21: 57.591841 | AL21: 64.096595 | AM21: 120.48435 | AN21: 11.100646 | AO21: 10.16145 | AP21: 36.135517 | AQ21: 17.872781 | AR21: 87.725785 | AS21: 31.25823 | AT21: 310.99156 | AU21: 123.35785 | AV21: 3233.7511 | AW21: 477.06804 | AX21: 1018.9027 | AY21: 119980.17 | AZ21: 6.6425869 | BA21: 85.926345 | BB21: 92.57054 | BC21: 45.535683 | BD21: 31.346846 | BE21: 51.154896 | BF21: =H21*5993.43-AY21 -> -16653.433 | BG21: =W21*8701-AG21 -> -1637.3298 | BH21: =BG21/AG21*100 -> -24.181793 | BK21: ='для графера'!F47/'для графера'!N47 -> 2.3304522 | BL21: ='для графера'!F47/'для графера'!B47 -> 1.1992913 | BM21: =AW21/AQ21 -> 26.692435 | BN21: ='для графера'!B47/'для графера'!N47 -> 1.9431911 | BO21: =AV21/AP21 -> 89.48955
A22: 19ТР-18 | C22: 17 | D22: 35.04 | E22: 21 | F22: 76 | G22: 35.04 | H22: 2.54 | I22: 2.28 | K22: 23.16 | L22: 0.39 | M22: 0.39 | N22: 32.4 | P22: 0.26 | W22: 0 | X22: 0 | AC22: 96.5 | AD22: 27.829694 | AE22: 2.7445869 | AF22: 217.71358 | AG22: 2415.2677 | AH22: 318.16057 | AI22: 42.130249 | AJ22: 116.25567 | AK22: 25.547944 | AL22: 27.078653 | AM22: 40.432943 | AN22: 6.0178326 | AO22: 7.2860456 | AP22: 11.421512 | AQ22: 7.3478149 | AR22: 36.520774 | AS22: 13.2316 | AT22: 195.82581 | AU22: 111.92299 | AV22: 1541.0222 | AW22: 231.27585 | AX22: 2787.8035 | AY22: 53028.989 | AZ22: 6.8537059 | BA22: 204.91441 | BB22: 37.624719 | BC22: 19.873483 | BD22: 12.975295 | BE22: 22.883521 | BF22: =H22*5993.43-AY22 -> -37805.677 | BK22: ='для графера'!F48/'для графера'!N48 -> 2.3554697 | BL22: ='для графера'!F48/'для графера'!B48 -> 0.58308468 | BM22: =AW22/AQ22 -> 31.47546 | BN22: ='для графера'!B48/'для графера'!N48 -> 4.03967 | BO22: =AV22/AP22 -> 134.92279
A23: 19ТР-4 | C23: 1 | D23: 25.48 | E23: 22 | F23: 77 | G23: 25.48 | H23: 15.39 | I23: 1.26 | K23: 17.4 | L23: 1.65 | M23: 0.41 | N23: 30.36 | P23: 0.48 | Q23: 0 | U23: 0 | W23: 5.3 | X23: 0 | Y23: 0 | AC23: 97.73 | AD23: 21.155449 | AE23: 4.7988572 | AF23: 201.72298 | AG23: 63250.07 | AH23: 217.30704 | AI23: 167.31713 | AJ23: 364.92042 | AK23: 344.63183 | AL23: 379.97022 | AM23: 1128.028 | AN23: 1.8128954 | AO23: 4.329425 | AP23: 64.831413 | AQ23: 97.56413 | AR23: 428.42099 | AS23: 74.975128 | AT23: 303.05699 | AU23: 55.227439 | AV23: 283.54327 | AW23: 2660.626 | AX23: 766.52651 | AY23: 155640.11 | AZ23: 5.3177391 | BA23: 29.233751 | BB23: 260.01303 | BC23: 318.92862 | BD23: 74.663187 | BE23: 329.30006 | BF23: =H23*5993.43-AY23 -> -63401.226 | BG23: =W23*8701-AG23 -> -17134.77 | BH23: =BG23/AG23*100 -> -27.090516 | BK23: ='для графера'!F49/'для графера'!N49 -> 0.58291391 | BL23: ='для графера'!F49/'для графера'!B49 -> 4.6929122 | BM23: =AW23/AQ23 -> 27.270535 | BN23: ='для графера'!B49/'для графера'!N49 -> 0.12421155 | BO23: =AV23/AP23 -> 4.3735476
A24: 19ТР-4 | C24: 2 | D24: 30.02 | E24: 22 | F24: 78 | G24: 30.02 | H24: 10.95 | I24: 1.47 | K24: 21.23 | L24: 1.11 | M24: 0.32 | N24: 32.19 | P24: 0.16 | Q24: 0 | U24: 0 | W24: 0 | X24: 0 | Y24: 0 | AC24: 97.44 | AD24: 24.128174 | AE24: 1.7206264 | AF24: 37.874223 | AG24: 4692.2572 | AH24: 282.15098 | AI24: 88.127256 | AJ24: 192.33135 | AK24: 38.16442 | AL24: 39.063105 | AM24: 73.986058 | AN24: 4.0096311 | AO24: 4.5018028 | AP24: 7.9857191 | AQ24: 11.541218 | AR24: 59.564952 | AS24: 25.409593 | AT24: 344.69829 | AU24: 45.106601 | AV24: 346.14573 | AW24: 299.00472 | AX24: 727.38314 | AY24: 31898.459 | AZ24: 3.4154736 | BA24: 3.1342608 | BB24: 82.234482 | BC24: 21.948699 | BD24: 25.595278 | BE24: 32.908536 | BF24: =H24*5993.43-AY24 -> 33729.6 | BK24: ='для графера'!F50/'для графера'!N50 -> 4.4612747 | BL24: ='для графера'!F50/'для графера'!B50 -> 3.0264051 | BM24: =AW24/AQ24 -> 25.907552 | BN24: ='для графера'!B50/'для графера'!N50 -> 1.4741168 | BO24: =AV24/AP24 -> 43.345593
A25: 19ТР-4 | C25: 25 | D25: 31.95 | E25: 23 | F25: 79 | G25: 31.95 | H25: 8.4 | I25: 1.97 | K25: 22.04 | L25: 0.96 | M25: 0.22 | N25: 32.74 | P25: 0.14 | Q25: 0 | U25: 0 | W25: 0 | X25: 0 | Y25: 0.23 | AC25: 98.66 | AD25: 26.824959 | AE25: 11.555289 | AF25: 308.32914 | AG25: 75783.192 | AH25: 172.23304 | AI25: 204.58702 | AJ25: 450.04944 | AK25: 519.80649 | AL25: 605.39554 | AM25: 1305.4875 | AN25: 1.3830422 | AO25: 5.7972277 | AP25: 90.861199 | AQ25: 140.11129 | AR25: 618.74001 | AS25: 95.115768 | AT25: 288.42039 | AU25: 39.873802 | AV25: 262.13161 | AW25: 4068.8842 | AX25: 1088.1476 | AY25: 205232.35 | AZ25: 3.3370304 | BA25: 27.812966 | BB25: 366.66404 | BC25: 528.36255 | BD25: 94.672837 | BE25: 500.36581 | BF25: =H25*5993.43-AY25 -> -154887.53 | BK25: ='для графера'!F51/'для графера'!N51 -> 0.43023283 | BL25: ='для графера'!F51/'для графера'!B51 -> 7.9478077 | BM25: =AW25/AQ25 -> 29.040373 | BN25: ='для графера'!B51/'для графера'!N51 -> 0.054132264 | BO25: =AV25/AP25 -> 2.8849675

Sheet Таблица полная Cpx
A1: № образца | B1: порода | C1: №анализа EPMA | D1: SiO2 | E1: кружок | F1: точка_SIMS | G1: Spectrum | H1: Na | I1: Mg | J1: Al | K1: Si | L1: Ca | M1: Ti | N1: V | O1: Cr | P1: Mn | Q1: Fe | R1: Zr | S1: Ba | T1: S | U1: K | V1: Total | W1: 085Rb | X1: 087Rb_str | Y1: 088Sr | Z1: 090Zr | AA1: 140Ce | AB1: 149Sm | AC1: 158Gd | AD1: 167Er | AE1: 174Yb | AF1: 178Hf | AG1: 232Th | AH1: 238U | AI1: 181Ta | AJ1: 165Ho | AK1: 163Dy | AL1: 153Eu | AM1: 143Nd | AN1: 139La | AO1: 093Nb | AP1: 089Y | AQ1: 051V | AR1: 047Ti | AS1: 011B | AT1: 007Li | AU1: 158Gd str | AV1: 174Yb str | AW1: 153Eu str | AX1: 167Er str | AY1: delta Ti
A2: 18КЛ-08 | B2: айликит | C2: 1 | D2: 50.96 | E2: 1 | F2: 1 | G2: Sp 1-2 | H2: 1 | I2: 14.77 | J2: 4.8 | K2: 50.96 | L2: 21.64 | M2: 0.96 | O2: 0.32 | Q2: 5.4 | V2: 99.83 | W2: 6.2697571 | X2: -0.60671241 | Y2: 113.75456 | Z2: 39.586397 | AA2: 12.647466 | AB2: 2.5053689 | AC2: 5.1774419 | AD2: 0.69868289 | AE2: 0.73324747 | AF2: 2.4875661 | AG2: 0.039000265 | AH2: 0.022241212 | AI2: 0.1309343 | AJ2: 0.25391919 | AK2: 1.3634113 | AL2: 0.73207148 | AM2: 10.799938 | AN2: 3.2043013 | AO2: 0.5300223 | AP2: 4.4324983 | AQ2: 191.49396 | AR2: 5715.7053 | AS2: 1.8559861 | AT2: 0.87545848 | AU2: 2.4135607 | AV2: 0.41658689 | AW2: 0.72101103 | AX2: 0.55062626 | AY2: =M2*47.9*10000/(47.9+32)-AR2 -> 39.488665 | AZ2: =AY2*100/AR2 -> 0.69088
A3: 18КЛ-08 | C3: 4 (2) | D3: 44.88 | E3: 1 | F3: 2 | G3: Spectrum 2 | H3: 0.46 | I3: 12.34 | J3: 8.9 | K3: 44.88 | L3: 23.95 | M3: 3.54 | N3: 0 | O3: 0 | P3: 0.13 | Q3: 6.89 | R3: 0 | V3: 101.09 | W3: 6.8972287 | X3: -0.86126702 | Y3: 273.56103 | Z3: 534.1578 | AA3: 88.289068 | AB3: 12.269172 | AC3: 26.614827 | AD3: 2.2905893 | AE3: 2.3297069 | AF3: 26.724452 | AG3: 0.47294362 | AH3: 0.050653109 | AI3: 1.4762627 | AJ3: 0.79349072 | AK3: 4.4652715 | AL3: 3.1153266 | AM3: 63.531533 | AN3: 26.983289 | AO3: 5.9479744 | AP3: 13.988313 | AQ3: 126.40396 | AR3: 21507.626 | AS3: 2.6575017 | AT3: 1.9612598 | AU3: 8.6175257 | AV3: 1.127047 | AW3: 3.1297645 | AX3: 1.6479051 | AY3: =M3*47.9*10000/(47.9+32)-AR3 -> -285.34847 | AZ3: =AY3*100/AR3 -> -1.3267316
A4: 18КЛ-08 | C4: 30 | D4: 51.06 | E4: 2 | F4: 3 | G4: Sp 30-2 | H4: 0.87 | I4: 15.2 | J4: 4.41 | K4: 51.06 | L4: 21.88 | M4: 0.94 | O4: 0.46 | Q4: 4.74 | V4: 99.55 | W4: 5.317139 | X4: -4.9107492 | Y4: 147.0874 | Z4: 42.244422 | AA4: 15.399267 | AB4: 2.9392133 | AC4: 5.7556148 | AD4: 0.71409898 | AE4: 0.87152783 | AF4: 2.4842751 | AG4: 0.1088788 | AH4: 0.028330791 | AI4: 0.21174345 | AJ4: 0.25583037 | AK4: 1.5000172 | AL4: 0.85420325 | AM4: 12.773196 | AN4: 4.4122337 | AO4: 1.1821999 | AP4: 5.0679038 | AQ4: 165.64324 | AR4: 5665.4576 | AS4: 3.3167497 | AT4: 1.0150536 | AU4: 1.83578 | AV4: 0.58841221 | AW4: 0.80161229 | AX4: 0.54949122 | AY4: =M4*47.9*10000/(47.9+32)-AR4 -> -30.163449 | AZ4: =AY4*100/AR4 -> -0.53240977
A5: 18КЛ-08 | C5: 34 | D5: 42.8 | E5: 2 | F5: 4 | G5: Sp 34-2 | H5: 0.49 | I5: 11.39 | J5: 9.2 | K5: 42.8 | L5: 23.34 | M5: 4.2 | Q5: 7.59 | V5: 99.02 | W5: 7.466467 | X5: 0.4489883 | Y5: 233.4751 | Z5: 387.9352 | AA5: 79.562728 | AB5: 11.2969 | AC5: 26.046133 | AD5: 2.2041447 | AE5: 2.4055674 | AF5: 18.358042 | AG5: 0.68480162 | AH5: 0.035635398 | AI5: 1.0411566 | AJ5: 0.74374999 | AK5: 4.3181595 | AL5: 3.0078567 | AM5: 60.870966 | AN5: 24.218171 | AO5: 4.6954123 | AP5: 13.977072 | AQ5: 123.65221 | AR5: 17654.302 | AS5: 2.1783497 | AT5: 1.2713946 | AU5: 7.4875038 | AV5: 1.2497233 | AW5: 2.9869709 | AX5: 1.5907826 | AY5: =M5*47.9*10000/(47.9+32)-AR5 -> 7524.6713 | AZ5: =AY5*100/AR5 -> 42.622309
A6: 18КЛ-17 | B6: мела-айликит | C6: 47 | D6: 52.2 | E6: 3 | F6: 5 | G6: 47 | H6: 0.72 | I6: 15.64 | J6: 3.21 | K6: 52.2 | L6: 21.95 | M6: 0.51 | N6: 0.07 | O6: 0.18 | P6: 0.14 | Q6: 4.85 | R6: 0 | V6: 99.47 | W6: 5.7241321 | X6: 0.090510055 | Y6: 179.41818 | Z6: 35.832585 | AA6: 23.590693 | AB6: 4.3341367 | AC6: 9.167819 | AD6: 0.99193093 | AE6: 1.0501776 | AF6: 2.1955887 | AG6: 0.080380048 | AH6: 0.028484865 | AI6: 0.20494724 | AJ6: 0.35360237 | AK6: 2.0152786 | AL6: 1.2366152 | AM6: 19.330848 | AN6: 6.7395975 | AO6: 1.2648833 | AP6: 6.4987432 | AQ6: 166.70505 | AR6: 3437.3159 | AS6: 3.0752481 | AT6: 2.9518066 | AU6: 3.6462738 | AV6: 0.51292301 | AW6: 1.2202353 | AX6: 0.74136067 | AY6: =M6*47.9*10000/(47.9+32)-AR6 -> -379.86906 | AZ6: =AY6*100/AR6 -> -11.051328
A7: 18КЛ-17 | C7: 46 | D7: 51.81 | E7: 3 | F7: 6 | G7: 46 | H7: 0.77 | I7: 15.61 | J7: 3.11 | K7: 51.81 | L7: 21.85 | M7: 0.65 | N7: 0 | O7: 1.08 | P7: 0.12 | Q7: 4.35 | R7: 0 | V7: 99.47 | W7: 5.3678865 | X7: -3.5747287 | Y7: 178.14837 | Z7: 40.454051 | AA7: 24.396056 | AB7: 4.1570711 | AC7: 8.9022251 | AD7: 0.9824852 | AE7: 1.0308241 | AF7: 2.3354505 | AG7: 0.13691393 | AH7: 0.033814344 | AI7: 0.20939139 | AJ7: 0.35905739 | AK7: 2.13034 | AL7: 1.2662844 | AM7: 19.305111 | AN7: 7.6189082 | AO7: 1.9654638 | AP7: 6.9891741 | AQ7: 151.76138 | AR7: 4187.4483 | AS7: 3.6061109 | AT7: 4.132797 | AU7: 3.9142167 | AV7: 0.52250773 | AW7: 1.1962598 | AX7: 0.73683821 | AY7: =M7*47.9*10000/(47.9+32)-AR7 -> -290.70239 | AZ7: =AY7*100/AR7 -> -6.9422323
A8: 18КЛ-17 | C8: 45 | D8: 46.89 | E8: 3 | F8: 7 | G8: 45 | H8: 0.38 | I8: 13.48 | J8: 6.2 | K8: 46.89 | L8: 23.89 | M8: 2.35 | N8: 0 | O8: 0 | P8: 0 | Q8: 6.09 | R8: 0 | V8: 99.28 | W8: 7.0661401 | X8: 2.0201758 | Y8: 321.79407 | Z8: 338.10856 | AA8: 76.497649 | AB8: 10.725516 | AC8: 25.065418 | AD8: 2.2048777 | AE8: 2.3477336 | AF8: 15.374663 | AG8: 0.33805237 | AH8: 0.053797336 | AI8: 0.97360095 | AJ8: 0.78676217 | AK8: 4.2638078 | AL8: 2.9941969 | AM8: 61.724435 | AN8: 25.476114 | AO8: 5.0520723 | AP8: 14.183493 | AQ8: 108.36753 | AR8: 15491.642 | AS8: 3.1126163 | AT8: 0.63669521 | AU8: 6.9735429 | AV8: 1.2767744 | AW8: 2.9502012 | AX8: 1.5990661 | AY8: =M8*47.9*10000/(47.9+32)-AR8 -> -1403.4064 | AZ8: =AY8*100/AR8 -> -9.05912
A9: 18КЛ-17 | C9: 43 | D9: 47.97 | E9: 3 | F9: 8 | G9: 43 | H9: 0.4 | I9: 13.73 | J9: 5.59 | K9: 47.97 | L9: 23.82 | M9: 2.07 | N9: 0 | O9: 0 | P9: 0.14 | Q9: 5.93 | R9: 0 | V9: 99.66 | W9: 6.5248333 | X9: 2.6322442 | Y9: 296.40007 | Z9: 273.83004 | AA9: 67.822171 | AB9: 10.119292 | AC9: 23.831064 | AD9: 2.1328826 | AE9: 2.2971071 | AF9: 12.327008 | AG9: 0.26202198 | AH9: 0.026726825 | AI9: 0.64045729 | AJ9: 0.72667765 | AK9: 4.2906801 | AL9: 2.6841933 | AM9: 51.143521 | AN9: 22.015718 | AO9: 2.447026 | AP9: 13.586642 | AQ9: 84.927853 | AR9: 11294.279 | AS9: 3.9621413 | AT9: 0.49489563 | AU9: 7.7114234 | AV9: 1.1327748 | AW9: 2.6409883 | AX9: 1.5905666 | AY9: =M9*47.9*10000/(47.9+32)-AR9 -> 1115.3583 | AZ9: =AY9*100/AR9 -> 9.875427
A10: 18КЛ-17 | C10: 35 | D10: 52.29 | E10: 4 | F10: 9 | G10: 35 | H10: 0.83 | I10: 15.85 | J10: 2.42 | K10: 52.29 | L10: 21.84 | M10: 0.59 | N10: 0 | O10: 0.5 | P10: 0.11 | Q10: 4.5 | R10: 0 | V10: 98.94 | W10: 5.3584004 | X10: -2.0369445 | Y10: 151.26007 | Z10: 30.012708 | AA10: 20.474902 | AB10: 3.258695 | AC10: 6.8377719 | AD10: 0.85417435 | AE10: 0.92734691 | AF10: 2.1311603 | AG10: 0.21705619 | AH10: 0.04975449 | AI10: 0.20811568 | AJ10: 0.30495064 | AK10: 1.9015377 | AL10: 1.1508779 | AM10: 18.112327 | AN10: 7.6838488 | AO10: 1.83354 | AP10: 6.0432252 | AQ10: 181.16753 | AR10: 4479.4553 | AS10: 8.906436 | AT10: 1.1529294 | AU10: 1.7717787 | AV10: 0.66723031 | AW10: 1.072706 | AX10: 0.63389861 | AY10: =M10*47.9*10000/(47.9+32)-AR10 -> -942.40897 | AZ10: =AY10*100/AR10 -> -21.038473
A11: 18КЛ-17 | C11: 36 | D11: 52.53 | E11: 4 | F11: 10 | G11: 36 | H11: 0.88 | I11: 15.79 | J11: 2.35 | K11: 52.53 | L11: 21.77 | M11: 0.55 | N11: 0 | O11: 0.61 | P11: 0.15 | Q11: 4.42 | R11: 0 | V11: 99.06 | W11: 6.1968263 | X11: 2.8103096 | Y11: 178.72574 | Z11: 45.055448 | AA11: 23.457566 | AB11: 3.6047868 | AC11: 7.1424107 | AD11: 0.87360241 | AE11: 0.83450126 | AF11: 1.8911827 | AG11: 0.29455357 | AH11: 0.40278415 | AI11: 0.19939966 | AJ11: 0.27846157 | AK11: 1.699415 | AL11: 1.0563291 | AM11: 16.178842 | AN11: 7.5193613 | AO11: 6.356972 | AP11: 5.52436 | AQ11: 133.31578 | AR11: 3758.1208 | AS11: 31.340946 | AT11: 3.7638965 | AU11: 2.7784551 | AV11: 0.47981463 | AW11: 1.009546 | AX11: 0.66629632 | AY11: =M11*47.9*10000/(47.9+32)-AR11 -> -460.8742 | AZ11: =AY11*100/AR11 -> -12.263422
A12: 18КЛ-17 | C12: 37 | D12: 49.29 | E12: 4 | F12: 11 | G12: 37 | H12: 0.47 | I12: 14.36 | J12: 4.39 | K12: 49.29 | L12: 23.59 | M12: 1.5 | N12: 0 | O12: 0.47 | P12: 0.07 | Q12: 5.17 | R12: 0 | V12: 99.32 | W12: 7.9951992 | X12: -4.1410276 | Y12: 311.90671 | Z12: 497.75147 | AA12: 103.63148 | AB12: 15.840966 | AC12: 33.985356 | AD12: 2.9897178 | AE12: 3.3919433 | AF12: 23.705347 | AG12: 0.7034637 | AH12: 0.020465832 | AI12: 1.3912296 | AJ12: 1.0418337 | AK12: 6.3294663 | AL12: 4.0152315 | AM12: 78.930718 | AN12: 32.152854 | AO12: 5.6717566 | AP12: 19.498347 | AQ12: 110.95856 | AR12: 16514.57 | AS12: 4.7216868 | AT12: 0.62117677 | AU12: 11.980495 | AV12: 1.7131512 | AW12: 4.003315 | AX12: 2.1676537 | AY12: =M12*47.9*10000/(47.9+32)-AR12 -> -7522.0795 | AZ12: =AY12*100/AR12 -> -45.54814
A13: 19КЛ-23 | B13: мончикит | C13: 1 | D13: 50.73 | E13: 5 | F13: 12 | G13: 1 | H13: 1.65 | I13: 11.21 | J13: 5.04 | K13: 50.73 | L13: 20.16 | M13: 0.61 | O13: 0.13 | P13: 0.16 | Q13: 10.15 | V13: 99.82 | W13: 12.199805 | X13: 1.1584811 | Y13: 42.067918 | Z13: 86.043605 | AA13: 81.564503 | AB13: 19.72166 | AC13: 36.936698 | AD13: 1.9131338 | AE13: 2.5116132 | AF13: 5.9260276 | AG13: 0.060300038 | AH13: 0.030565515 | AI13: 0.28914508 | AJ13: 0.87673605 | AK13: 6.3307521 | AL13: 2.9229416 | AM13: 89.699342 | AN13: 14.990774 | AO13: 0.24494972 | AP13: 14.025102 | AQ13: 457.55128 | AR13: 3888.3338 | AS13: 1.8130521 | AT13: 38.631133 | AU13: 13.408921 | AV13: 0.44916038 | AW13: 2.883468 | AX13: 1.3210256 | AY13: =M13*47.9*10000/(47.9+32)-AR13 -> -231.38765 | AZ13: =AY13*100/AR13 -> -5.9508176
A14: 19КЛ-23 | C14: 2 | D14: 52.41 | E14: 5 | F14: 13 | G14: 2 | H14: 0.77 | I14: 15.63 | J14: 2.57 | K14: 52.41 | L14: 22.37 | M14: 0.44 | O14: 0.26 | P14: 0.1 | Q14: 4.72 | V14: 99.28 | W14: 5.7674317 | X14: 0.26485708 | Y14: 167.04373 | Z14: 28.728531 | AA14: 11.343575 | AB14: 2.3808903 | AC14: 4.8740944 | AD14: 1.0379092 | AE14: 1.1048262 | AF14: 1.9343872 | AG14: 0.026361928 | AH14: 0.035247235 | AI14: 0.1580091 | AJ14: 0.31183479 | AK14: 1.5897898 | AL14: 3.0686604 | AM14: 8.6411615 | AN14: 3.899657 | AO14: 0.74348611 | AP14: 6.2579074 | AQ14: 131.32549 | AR14: 2758.9932 | AS14: 2.3470222 | AT14: 1.5191808 | AU14: 2.558535 | AV14: 0.7627107 | AW14: 1.1320435 | AX14: 0.80544881 | AY14: =M14*47.9*10000/(47.9+32)-AR14 -> -121.19596 | AZ14: =AY14*100/AR14 -> -4.3927604
A15: 19КЛ-23 | C15: 3 | D15: 48.97 | E15: 5 | F15: 14 | G15: 3 | H15: 0.48 | I15: 13.62 | J15: 4.01 | K15: 48.97 | L15: 23.65 | M15: 1.35 | O15: 0 | P15: 0.11 | Q15: 7.05 | V15: 99.24 | W15: 11.901714 | X15: 3.742728 | Y15: 307.2146 | Z15: 261.45485 | AA15: 41.047441 | AB15: 6.8873435 | AC15: 14.760206 | AD15: 2.3815086 | AE15: 3.2460498 | AF15: 11.607094 | AG15: 0.23625712 | AH15: 0.061351111 | AI15: 0.60548577 | AJ15: 0.80346968 | AK15: 4.0733348 | AL15: 2.0158571 | AM15: 28.040127 | AN15: 14.756811 | AO15: 6.3994725 | AP15: 16.93 | AQ15: 103.36284 | AR15: 8486.8923 | AS15: 4.5962429 | AT15: 3.9412657 | AU15: 5.5974638 | AV15: 2.3863182 | AW15: 1.9936166 | AX15: 1.9721277 | AY15: =M15*47.9*10000/(47.9+32)-AR15 -> -393.65074 | AZ15: =AY15*100/AR15 -> -4.6383379
A16: 19КЛ-23 | C16: - | D16: 52.51 | E16: 14 | F16: 15 | G16: 22 | H16: 1.53 | I16: 13.91 | J16: 3.13 | K16: 52.51 | L16: 21.23 | M16: 0.65 | N16: 0 | O16: 0.08 | P16: 0.17 | Q16: 6.93 | V16: 100.15 | W16: 12.862335 | X16: 1.2175857 | Y16: 46.880584 | Z16: 133.96218 | AA16: 173.89637 | AB16: 20.467397 | AC16: 62.482763 | AD16: 6.2214161 | AE16: 6.8992879 | AF16: 7.8549143 | AG16: 0.52234779 | AH16: 0.041060064 | AI16: 0.87120089 | AJ16: 2.0675403 | AK16: 11.201601 | AL16: 3.719521 | AM16: 108.17527 | AN16: 58.402918 | AO16: 0.11906701 | AP16: 45.546004 | AQ16: 408.90856 | AR16: 3763.0432 | AS16: 2.2406152 | AT16: 60.252671 | AU16: 16.682003 | AV16: 3.6025873 | AW16: 3.6065967 | AX16: 5.4808164 | AY16: =M16*47.9*10000/(47.9+32)-AR16 -> 133.70275 | AZ16: =AY16*100/AR16 -> 3.5530485
A17: 19КЛ-23 | C17: - | D17: 46.74 | E17: 14 | F17: 16 | G17: 23 | H17: 0.88 | I17: 11.73 | J17: 6.34 | K17: 46.74 | L17: 23.03 | M17: 1.95 | N17: 0.09 | O17: 0 | P17: 0.11 | Q17: 8.86 | V17: 99.73 | W17: 7.1019129 | X17: -0.72512734 | Y17: 252.37588 | Z17: 119.45013 | AA17: 27.708105 | AB17: 4.7135664 | AC17: 9.996117 | AD17: 1.6915624 | AE17: 1.7076894 | AF17: 6.3951335 | AG17: 0.10320521 | AH17: 0.017778214 | AI17: 0.39808056 | AJ17: 0.47254372 | AK17: 2.5080954 | AL17: 1.3965602 | AM17: 20.110959 | AN17: 9.6376252 | AO17: 1.5510728 | AP17: 9.7677784 | AQ17: 105.34146 | AR17: 7660.9144 | AS17: 3.3362662 | AT17: 0.59530807 | AU17: 3.5543442 | AV17: 1.1960015 | AW17: 1.4136163 | AX17: 1.4012822 | AY17: =M17*47.9*10000/(47.9+32)-AR17 -> 4029.3234 | AZ17: =AY17*100/AR17 -> 52.595854
A18: 19КН-05 | B18: саннаит | C18: 26 | D18: 52.38 | E18: 6 | F18: 17 | G18: 26 | H18: 0.46 | I18: 16.16 | J18: 1.77 | K18: 52.38 | L18: 22.62 | M18: 1.11 | N18: 0 | O18: 0.58 | P18: 0.11 | Q18: 4.7 | S18: 0 | V18: 99.89 | W18: 6.3071829 | X18: -1.1020453 | Y18: 294.43366 | Z18: 55.466701 | AA18: 39.70931 | AB18: 6.9341299 | AC18: 15.191091 | AD18: 1.7574025 | AE18: 1.8065517 | AF18: 3.6262259 | AG18: 0.060917833 | AH18: 0.014975483 | AI18: 0.25879344 | AJ18: 0.60325197 | AK18: 3.4113311 | AL18: 2.1309462 | AM18: 34.472136 | AN18: 12.460419 | AO18: 0.71705386 | AP18: 11.541345 | AQ18: 112.52522 | AR18: 7338.4166 | AS18: 4.508594 | AT18: 3.7585306 | AU18: 5.4071604 | AV18: 0.99283736 | AW18: 2.0821297 | AX18: 1.3298458 | AY18: =M18*47.9*10000/(47.9+32)-AR18 -> -683.97354 | AZ18: =AY18*100/AR18 -> -9.3204513
A19: 19КН-05 | C19: 27 | D19: 50.59 | E19: 6 | F19: 18 | G19: 27 | H19: 0.62 | I19: 15.18 | J19: 3.13 | K19: 50.59 | L19: 22.47 | M19: 1.42 | N19: 0 | O19: 1 | P19: 0.09 | Q19: 5.11 | S19: 0.16 | V19: 99.77 | W19: 6.5084042 | X19: -4.0592769 | Y19: 339.71506 | Z19: 79.420353 | AA19: 54.068903 | AB19: 8.1364522 | AC19: 18.423898 | AD19: 2.0283948 | AE19: 1.966183 | AF19: 4.6432482 | AG19: 0.10807809 | AH19: 0.015603484 | AI19: 0.33043393 | AJ19: 0.65169094 | AK19: 3.9331987 | AL19: 2.3344244 | AM19: 44.462729 | AN19: 17.955192 | AO19: 1.1953086 | AP19: 12.25928 | AQ19: 151.13381 | AR19: 9861.7587 | AS19: 2.2385943 | AT19: 1.2271486 | AU19: 5.7913712 | AV19: 1.0594654 | AW19: 2.3208862 | AX19: 1.5518104 | AY19: =M19*47.9*10000/(47.9+32)-AR19 -> -1348.8676 | AZ19: =AY19*100/AR19 -> -13.677759
A20: 19КН-05 | C20: 28 | D20: 50.13 | E20: 6 | F20: 19 | G20: 28 | H20: 0.56 | I20: 14.95 | J20: 3.01 | K20: 50.13 | L20: 22.91 | M20: 1.74 | N20: 0 | O20: 0.74 | P20: 0 | Q20: 5.26 | S20: 0 | V20: 99.29 | W20: 6.7027531 | X20: -12.566883 | Y20: 362.86527 | Z20: 113.02517 | AA20: 62.163799 | AB20: 9.4431374 | AC20: 21.142066 | AD20: 2.2035201 | AE20: 2.3855797 | AF20: 6.5915915 | AG20: 0.16347783 | AH20: 0.047722691 | AI20: 0.36982138 | AJ20: 0.67991173 | AK20: 4.021611 | AL20: 2.522147 | AM20: 46.230756 | AN20: 19.841394 | AO20: 1.3485891 | AP20: 12.060753 | AQ20: 145.26781 | AR20: 11641.253 | AS20: 3.57366 | AT20: 1.1081096 | AU20: 7.64348 | AV20: 1.3183557 | AW20: 2.5270492 | AX20: 1.6846011 | AY20: =M20*47.9*10000/(47.9+32)-AR20 -> -1209.9638 | AZ20: =AY20*100/AR20 -> -10.393759
A21: 19КН-31 | B21: мончикит | C21: 1 | D21: 52.14 | E21: 7 | F21: 20 | G21: 1 | H21: 0.6 | I21: 15.33 | J21: 2.42 | K21: 52.14 | L21: 23.62 | M21: 0.61 | N21: 0 | O21: 0 | P21: 0.07 | Q21: 4.69 | S21: 0 | V21: 99.49 | W21: 12.705062 | X21: 15.328217 | Y21: 3062.9269 | Z21: 26.645303 | AA21: 7.7443006 | AB21: 1.2090446 | AC21: 2.7394855 | AD21: 0.39054835 | AE21: 0.43082511 | AF21: 1.6583249 | AG21: 0.060141687 | AH21: 0.013625962 | AI21: 0.13759006 | AJ21: 0.15550258 | AK21: 0.76809476 | AL21: 1.0385977 | AM21: 5.4607898 | AN21: 2.4457923 | AO21: 0.58129033 | AP21: 6.236897 | AQ21: 48.371778 | AR21: 2230.9758 | AS21: 2.6772618 | AT21: 4.3324506 | AU21: 1.1601043 | AV21: 0.27133912 | AW21: 0.3960665 | AX21: 0.30921774 | AY21: =M21*47.9*10000/(47.9+32)-AR21 -> 1425.9704 | AZ21: =AY21*100/AR21 -> 63.916893
A22: 19КН-31 | C22: 2 | D22: 50.74 | E22: 7 | F22: 21 | G22: 2 | H22: 0.76 | I22: 14.12 | J22: 3.74 | K22: 50.74 | L22: 23.3 | M22: 1 | N22: 0 | O22: 0 | P22: 0.15 | Q22: 6.3 | S22: 0 | V22: 100.1 | W22: 7.0583385 | X22: -2.9367245 | Y22: 332.58565 | Z22: 65.101168 | AA22: 21.397476 | AB22: 3.5017192 | AC22: 7.6558696 | AD22: 1.0599502 | AE22: 1.1241732 | AF22: 3.4638745 | AG22: 0.044129074 | AH22: 0.015328795 | AI22: 0.18068902 | AJ22: 0.34182449 | AK22: 1.8797601 | AL22: 0.99866684 | AM22: 16.029408 | AN22: 7.1138216 | AO22: 0.53741223 | AP22: 7.0959398 | AQ22: 87.172998 | AR22: 4827.8899 | AS22: 2.7430276 | AT22: 1.4298624 | AU22: 2.856622 | AV22: 0.71881437 | AW22: 0.99051866 | AX22: 0.85655134 | AY22: =M22*47.9*10000/(47.9+32)-AR22 -> 1167.1038 | AZ22: =AY22*100/AR22 -> 24.174202
A23: 19КН-31 | C23: 3 | D23: 50.26 | E23: 7 | F23: 22 | G23: 3 | H23: 0.94 | I23: 13.23 | J23: 3.9 | K23: 50.26 | L23: 23.02 | M23: 0.98 | N23: 0 | O23: 0 | P23: 0.11 | Q23: 7.49 | S23: 0 | V23: 99.94 | W23: 15.875543 | X23: 2.7506537 | Y23: 605.89052 | Z23: 548.00028 | AA23: 56.087389 | AB23: 8.7854592 | AC23: 19.693979 | AD23: 4.0844585 | AE23: 6.6407777 | AF23: 22.030066 | AG23: 0.12278483 | AH23: 0.11880933 | AI23: 0.8560302 | AJ23: 1.3564681 | AK23: 7.0957314 | AL23: 3.0728512 | AM23: 44.824818 | AN23: 24.121045 | AO23: 6.0092954 | AP23: 25.391311 | AQ23: 95.88493 | AR23: 7086.8638 | AS23: 5.3339725 | AT23: 46.88644 | AU23: 7.0427943 | AV23: 5.5388131 | AW23: 2.8642291 | AX23: 3.4963009 | AY23: =M23*47.9*10000/(47.9+32)-AR23 -> -1211.77 | AZ23: =AY23*100/AR23 -> -17.098818
A24: 19КН-31 | C24: 32 | D24: 51.54 | E24: 8 | F24: 23 | G24: 32 | H24: 0.74 | I24: 14.39 | J24: 2.9 | K24: 51.54 | L24: 23.32 | M24: 0.67 | N24: 0 | O24: 0 | P24: 0.11 | Q24: 6.22 | S24: 0 | V24: 99.9 | W24: 7.4934868 | X24: -0.90580378 | Y24: 307.62762 | Z24: 57.092453 | AA24: 19.144642 | AB24: 3.2679778 | AC24: 6.6257103 | AD24: 0.76646835 | AE24: 1.0580056 | AF24: 3.0174696 | AG24: 0.039845953 | AH24: 0.017072214 | AI24: 0.19212868 | AJ24: 0.30053936 | AK24: 1.8414512 | AL24: 0.93933282 | AM24: 14.214985 | AN24: 6.7159216 | AO24: 0.44445237 | AP24: 6.7683802 | AQ24: 89.883094 | AR24: 4548.9555 | AS24: 2.9797048 | AT24: 0.54275805 | AU24: 2.507805 | AV24: 0.68597574 | AW24: 0.92785656 | AX24: 0.57593685 | AY24: =M24*47.9*10000/(47.9+32)-AR24 -> -532.30969 | AZ24: =AY24*100/AR24 -> -11.7018
A25: 19КН-31 | C25: 33 | D25: 49.67 | E25: 8 | F25: 24 | G25: 33 | H25: 0.91 | I25: 13.08 | J25: 4.18 | K25: 49.67 | L25: 23.02 | M25: 1.18 | N25: 0 | O25: 0 | P25: 0.14 | Q25: 7.5 | S25: 0 | V25: 99.69 | W25: 8.9897927 | X25: 0.054399398 | Y25: 401.4482 | Z25: 144.96453 | AA25: 31.496488 | AB25: 4.9430721 | AC25: 11.192928 | AD25: 1.6785674 | AE25: 1.7664258 | AF25: 6.661772 | AG25: 0.060341468 | AH25: 0.019904392 | AI25: 0.3996061 | AJ25: 0.51749754 | AK25: 2.6895251 | AL25: 1.4689319 | AM25: 24.51778 | AN25: 11.289137 | AO25: 1.1171632 | AP25: 10.479247 | AQ25: 118.86175 | AR25: 6623.8937 | AS25: 2.1673039 | AT25: 0.76282415 | AU25: 3.6964006 | AV25: 1.1914324 | AW25: 1.42332 | AX25: 1.3862945 | AY25: =M25*47.9*10000/(47.9+32)-AR25 -> 450.19893 | AZ25: =AY25*100/AR25 -> 6.7965905
A26: 19КН-31 | C26: 34 | D26: 48.93 | E26: 8 | F26: 25 | G26: 34 | H26: 4.1 | I26: 2.4 | J26: 0.77 | K26: 48.93 | L26: 16.01 | M26: 1.2 | N26: 0.11 | O26: 0 | P26: 1.21 | Q26: 24.4 | S26: 0 | V26: 99.12 | W26: 21.222631 | X26: 24.708324 | Y26: 825.72512 | Z26: 427.6487 | AA26: 27.993396 | AB26: 3.4774367 | AC26: 9.3960234 | AD26: 2.1591252 | AE26: 5.1393484 | AF26: 8.8740015 | AG26: 0.06601321 | AH26: 0.016931874 | AI26: 0.87897365 | AJ26: 0.51742145 | AK26: 2.2254274 | AL26: 1.2595267 | AM26: 18.721907 | AN26: 9.8486148 | AO26: 3.1664252 | AP26: 9.9074093 | AQ26: 229.36692 | AR26: 7236.713 | AS26: 5.2841139 | AT26: 10.360855 | AU26: 2.9119693 | AV26: 4.6467804 | AW26: 1.1060259 | AX26: 1.9320074 | AY26: =M26*47.9*10000/(47.9+32)-AR26 -> -42.720515 | AZ26: =AY26*100/AR26 -> -0.59033038
A27: 19ТР-13 | C27: 15 | D27: 48.23 | E27: 9 | F27: 26 | G27: Spectrum 15 | H27: 0.31 | I27: 13.74 | J27: 5.25 | K27: 48.23 | L27: 23.9 | M27: 1.74 | N27: 0 | O27: 0 | P27: 0.12 | Q27: 6.42 | R27: 0 | S27: 0 | T27: 0 | U27: 0.04 | V27: 99.76 | W27: 7.5235501 | X27: 2.9768857 | Y27: 377.44944 | Z27: 337.51137 | AA27: 87.038142 | AB27: 11.64458 | AC27: 27.459542 | AD27: 2.6368784 | AE27: 2.8269717 | AF27: 12.741095 | AG27: 0.4049064 | AH27: 0.038472177 | AI27: 0.76228135 | AJ27: 0.88881474 | AK27: 5.0755493 | AL27: 3.2627447 | AM27: 62.214694 | AN27: 29.681002 | AO27: 3.3262544 | AP27: 16.17539 | AQ27: 93.841521 | AR27: 11371.639 | AS27: 1.9227199 | AT27: 3.1696708 | AU27: 9.2965507 | AV27: 1.5201142 | AW27: 3.2208061 | AX27: 1.9754992 | AY27: =M27*47.9*10000/(47.9+32)-AR27 -> -940.3503 | AZ27: =AY27*100/AR27 -> -8.2692588
A28: 19ТР-13 | C28: 16 | D28: 46.7 | E28: 9 | F28: 27 | G28: Spectrum 16 | H28: 0.35 | I28: 13.21 | J28: 6.27 | K28: 46.7 | L28: 23.69 | M28: 2.01 | N28: 0 | O28: 0 | P28: 0.08 | Q28: 7.1 | R28: 0 | S28: 0 | T28: 0 | U28: 0 | V28: 99.42 | W28: 32.199567 | X28: 20.117438 | Y28: 330.02362 | Z28: 467.5737 | AA28: 88.157593 | AB28: 12.202151 | AC28: 28.724458 | AD28: 3.1503177 | AE28: 3.6499582 | AF28: 20.804062 | AG28: 0.59083536 | AH28: 0.038074728 | AI28: 1.1105615 | AJ28: 1.0227887 | AK28: 5.9219667 | AL28: 3.8667573 | AM28: 62.911902 | AN28: 31.983858 | AO28: 4.7331937 | AP28: 19.700244 | AQ28: 119.49174 | AR28: 13182.517 | AS28: 8.5500295 | AT28: 14.485102 | AU28: 9.1543897 | AV28: 2.3061175 | AW28: 3.6139813 | AX28: 2.4082016 | AY28: =M28*47.9*10000/(47.9+32)-AR28 -> -1132.5797 | AZ28: =AY28*100/AR28 -> -8.5915283
A29: 19ТР-13 | C29: 17 | D29: 48.73 | E29: 9 | F29: 28 | G29: Spectrum 17 | H29: 0.33 | I29: 14.11 | J29: 4.95 | K29: 48.73 | L29: 23.87 | M29: 1.48 | N29: 0 | O29: 0.23 | P29: 0 | Q29: 5.57 | R29: 0 | S29: 0 | T29: 0.08 | U29: 0 | V29: 99.34 | W29: 10.573453 | X29: 6.4177783 | Y29: 706.32938 | Z29: 197.28811 | AA29: 60.351819 | AB29: 8.9243895 | AC29: 18.563768 | AD29: 1.8942139 | AE29: 1.6621713 | AF29: 10.553017 | AG29: 0.2963351 | AH29: 0.037115202 | AI29: 0.56317288 | AJ29: 0.63068522 | AK29: 3.6407866 | AL29: 2.8727566 | AM29: 48.340403 | AN29: 23.819145 | AO29: 2.089384 | AP29: 11.858795 | AQ29: 86.554133 | AR29: 10115.118 | AS29: 5.0702472 | AT29: 5.0628157 | AU29: 6.7070385 | AV29: 0.74753825 | AW29: 2.6466568 | AX29: 1.3507339 | AY29: =M29*47.9*10000/(47.9+32)-AR29 -> -1242.5276 | AZ29: =AY29*100/AR29 -> -12.283866
A30: 19ТР-13 | C30: 18 | D30: 40.96 | E30: 9 | F30: 29 | G30: Spectrum 18 | H30: 0.43 | I30: 10.56 | J30: 11.01 | K30: 40.96 | L30: 23.48 | M30: 4.08 | N30: 0 | O30: 0 | P30: 0.09 | Q30: 8.86 | R30: 0 | S30: 0 | T30: 0 | U30: 0 | V30: 99.48 | W30: 50.028926 | X30: 36.725905 | Y30: 838.17873 | Z30: 477.80883 | AA30: 158.94877 | AB30: 16.860864 | AC30: 44.383076 | AD30: 3.1519037 | AE30: 3.2080527 | AF30: 14.428307 | AG30: 1.2525752 | AH30: 0.40634529 | AI30: 3.1759661 | AJ30: 1.0361555 | AK30: 5.9035812 | AL30: 5.0264496 | AM30: 92.713616 | AN30: 58.383362 | AO30: 39.864034 | AP30: 18.427475 | AQ30: 195.3974 | AR30: 21140.272 | AS30: 14.696925 | AT30: 23.404303 | AU30: 11.545999 | AV30: 1.4715471 | AW30: 4.0954616 | AX30: 2.3109176 | AY30: =M30*47.9*10000/(47.9+32)-AR30 -> 3319.3023 | AZ30: =AY30*100/AR30 -> 15.701322
A31: 19ТР-13 | C31: 19 | D31: 46.5 | E31: 9 | F31: 30 | G31: Spectrum 19 | H31: 0.35 | I31: 13.12 | J31: 5.84 | K31: 46.5 | L31: 23.65 | M31: 1.88 | N31: 0 | O31: 0 | P31: 0 | Q31: 6.84 | R31: 0 | S31: 0 | T31: 0 | U31: 0.04 | V31: 98.22 | W31: 7.6819368 | X31: 2.602128 | Y31: 310.94164 | Z31: 362.70815 | AA31: 82.998929 | AB31: 11.361401 | AC31: 25.80087 | AD31: 2.6655703 | AE31: 2.9192552 | AF31: 15.343353 | AG31: 0.35099257 | AH31: 0.026439635 | AI31: 0.75744866 | AJ31: 0.92472524 | AK31: 5.2216056 | AL31: 3.2334535 | AM31: 60.087635 | AN31: 29.21912 | AO31: 2.8214033 | AP31: 17.733037 | AQ31: 91.78393 | AR31: 11793.815 | AS31: 2.720767 | AT31: 3.6271116 | AU31: 7.7030114 | AV31: 1.7857114 | AW31: 3.1724974 | AX31: 2.0141111 | AY31: =M31*47.9*10000/(47.9+32)-AR31 -> -523.22692 | AZ31: =AY31*100/AR31 -> -4.4364518
A32: 19ТР-13 | C32: 20 | D32: 42.37 | E32: 9 | F32: 31 | G32: Spectrum 20 | H32: 0.46 | I32: 11.21 | J32: 9.86 | K32: 42.37 | L32: 23.42 | M32: 3.48 | N32: 0 | O32: 0 | P32: 0.1 | Q32: 8.13 | R32: 0 | S32: 0 | T32: 0 | U32: 0 | V32: 99.05 | W32: 8.9360601 | X32: -2.4672577 | Y32: 462.95165 | Z32: 516.22221 | AA32: 141.1746 | AB32: 15.063815 | AC32: 39.577329 | AD32: 3.009215 | AE32: 3.2288317 | AF32: 18.557156 | AG32: 0.76666058 | AH32: 0.056445294 | AI32: 2.591896 | AJ32: 1.0320522 | AK32: 6.0454411 | AL32: 4.166868 | AM32: 93.410452 | AN32: 51.357644 | AO32: 14.696686 | AP32: 18.436505 | AQ32: 138.02691 | AR32: 22478.631 | AS32: 4.4882644 | AT32: 3.6047479 | AU32: 11.241085 | AV32: 1.5861666 | AW32: 4.0853188 | AX32: 2.1703117 | AY32: =M32*47.9*10000/(47.9+32)-AR32 -> -1616.0528 | AZ32: =AY32*100/AR32 -> -7.189285
A33: 19ТР-14 | C33: 7 | D33: 50.34 | E33: 10 | F33: 32 | G33: Spectrum 7 | H33: 2.05 | I33: 9.96 | J33: 2.66 | K33: 50.34 | L33: 21.02 | M33: 0.79 | N33: 0 | O33: 0 | P33: 0.37 | Q33: 11.97 | R33: 0 | V33: 99.17 | W33: 20.883264 | X33: 1.3240763 | Y33: 502.71203 | Z33: 456.42459 | AA33: 94.315468 | AB33: 5.82558 | AC33: 21.754036 | AD33: 1.8438908 | AE33: 3.1217671 | AF33: 13.067941 | AG33: 0.080455377 | AH33: 0.075093249 | AI33: 0.63034661 | AJ33: 0.52405681 | AK33: 2.9883657 | AL33: 2.0412639 | AM33: 37.968641 | AN33: 47.03474 | AO33: 3.4430801 | AP33: 12.018839 | AQ33: 115.71727 | AR33: 4939.3207 | AS33: 6.0104635 | AT33: 2.7164823 | AU33: 5.1138705 | AV33: 2.3162786 | AW33: 1.8441948 | AX33: 1.465193 | AY33: =M33*47.9*10000/(47.9+32)-AR33 -> -203.27562 | AZ33: =AY33*100/AR33 -> -4.1154569
A34: 19ТР-14 | C34: 8 | D34: 49.05 | E34: 10 | F34: 33 | G34: Spectrum 8 | H34: 2.02 | I34: 8.05 | J34: 2.89 | K34: 49.05 | L34: 20.5 | M34: 0.9 | N34: 0 | O34: 0 | P34: 0.4 | Q34: 15.03 | R34: 0 | V34: 98.84 | W34: 18.272635 | X34: -10.207059 | Y34: 659.78043 | Z34: 411.14232 | AA34: 53.753892 | AB34: 4.6679241 | AC34: 15.349666 | AD34: 1.4833921 | AE34: 2.5650999 | AF34: 9.1951859 | AG34: 0.10595009 | AH34: 0.017319738 | AI34: 0.65763799 | AJ34: 0.3957558 | AK34: 2.3374655 | AL34: 1.4575081 | AM34: 29.525405 | AN34: 18.704476 | AO34: 5.798352 | AP34: 7.8830958 | AQ34: 148.73099 | AR34: 6231.7241 | AS34: 3.0930204 | AT34: 2.0085265 | AU34: 4.0394271 | AV34: 1.9201826 | AW34: 1.4252995 | AX34: 1.1907127 | AY34: =M34*47.9*10000/(47.9+32)-AR34 -> -836.22969 | AZ34: =AY34*100/AR34 -> -13.418914
A35: 19ТР-14 | C35: 9 | D35: 50.13 | E35: 10 | F35: 34 | G35: Spectrum 9 | H35: 3.31 | I35: 6.72 | J35: 2.1 | K35: 50.13 | L35: 18.2 | M35: 0.66 | N35: 0 | O35: 0 | P35: 0.37 | Q35: 17.6 | R35: 0 | V35: 99.09 | W35: 23.515537 | X35: -3.3432181 | Y35: 616.0374 | Z35: 704.01086 | AA35: 41.730371 | AB35: 3.9374019 | AC35: 12.068659 | AD35: 1.4683491 | AE35: 3.412439 | AF35: 15.22542 | AG35: 0.058151578 | AH35: 0.019262079 | AI35: 0.30990595 | AJ35: 0.3780936 | AK35: 1.8395067 | AL35: 1.1230754 | AM35: 23.802069 | AN35: 15.550823 | AO35: 3.6059843 | AP35: 7.3817646 | AQ35: 194.33999 | AR35: 3764.5496 | AS35: 2.1823674 | AT35: 1.7185211 | AU35: 2.2256659 | AV35: 2.9776285 | AW35: 1.1016828 | AX35: 1.2421231 | AY35: =M35*47.9*10000/(47.9+32)-AR35 -> 192.1463 | AZ35: =AY35*100/AR35 -> 5.104098
A36: 19ТР-14 | C36: 10 | D36: 50.86 | E36: 10 | F36: 35 | G36: Spectrum 10 | H36: 3.45 | I36: 7.05 | J36: 1.69 | K36: 50.86 | L36: 17.87 | M36: 0.46 | N36: 0 | O36: 0 | P36: 0.39 | Q36: 17.05 | R36: 0 | V36: 98.82 | W36: 19.377521 | X36: -4.2445352 | Y36: 596.1431 | Z36: 547.90755 | AA36: 45.756576 | AB36: 3.8394404 | AC36: 11.976843 | AD36: 1.3290056 | AE36: 3.0554732 | AF36: 11.354868 | AG36: 0.16536054 | AH36: 0.041864036 | AI36: 0.22082839 | AJ36: 0.3557744 | AK36: 1.7720908 | AL36: 1.1214531 | AM36: 23.995388 | AN36: 17.155692 | AO36: 2.0922742 | AP36: 6.9192401 | AQ36: 159.44526 | AR36: 3796.7712 | AS36: 3.4064826 | AT36: 2.253926 | AU36: 2.1285191 | AV36: 2.6697955 | AW36: 1.0791513 | AX36: 1.1074063 | AY36: =M36*47.9*10000/(47.9+32)-AR36 -> -1039.074 | AZ36: =AY36*100/AR36 -> -27.367307
A37: 19ТР-16 | C37: 81 | D37: 49.02 | E37: 11 | F37: 36 | G37: Spectrum 81 | H37: 0.59 | I37: 14.05 | J37: 4.87 | K37: 49.02 | L37: 22.67 | M37: 1.16 | N37: 0 | O37: 0.53 | P37: 0.13 | Q37: 5.5 | S37: 0 | T37: 0 | U37: 0 | V37: 98.51 | W37: 7.1422628 | X37: -1.0180326 | Y37: 183.67501 | Z37: 53.535679 | AA37: 19.233536 | AB37: 3.435892 | AC37: 7.1063068 | AD37: 0.92347154 | AE37: 0.81115283 | AF37: 3.6861205 | AG37: 0.050841982 | AH37: 0.029039712 | AI37: 0.18664386 | AJ37: 0.2748063 | AK37: 1.603532 | AL37: 1.0263694 | AM37: 15.783766 | AN37: 6.4501395 | AO37: 0.85759707 | AP37: 5.4936706 | AQ37: 114.96509 | AR37: 8266.9389 | AS37: 2.2150068 | AT37: 2.4301407 | AU37: 2.3185333 | AV37: 0.46119172 | AW37: 1.0063131 | AX37: 0.71682931 | AY37: =M37*47.9*10000/(47.9+32)-AR37 -> -1312.7461 | AZ37: =AY37*100/AR37 -> -15.879471
A38: 19ТР-16 | C38: 82 | D38: 49.86 | E38: 11 | F38: 37 | G38: Spectrum 82 | H38: 0.67 | I38: 14.6 | J38: 4.08 | K38: 49.86 | L38: 22.52 | M38: 0.98 | N38: 0 | O38: 0.47 | P38: 0.07 | Q38: 5.09 | S38: 0 | T38: 0 | U38: 0 | V38: 98.32 | W38: 6.2729263 | X38: -0.58620786 | Y38: 168.39745 | Z38: 41.276406 | AA38: 15.665802 | AB38: 2.8546864 | AC38: 6.0077011 | AD38: 0.73837497 | AE38: 0.70417753 | AF38: 2.9874213 | AG38: 0.028112388 | AH38: 0.022893357 | AI38: 0.14411957 | AJ38: 0.24880546 | AK38: 1.420189 | AL38: 0.84825376 | AM38: 13.844918 | AN38: 5.1649386 | AO38: 0.57771342 | AP38: 4.9781527 | AQ38: 108.01393 | AR38: 6911.2499 | AS38: 2.6151611 | AT38: 2.2736971 | AU38: 2.2269163 | AV38: 0.37173082 | AW38: 0.81412442 | AX38: 0.57119789 | AY38: =M38*47.9*10000/(47.9+32)-AR38 -> -1036.156 | AZ38: =AY38*100/AR38 -> -14.99231
A39: 19ТР-16 | C39: 83 | D39: 45.87 | E39: 11 | F39: 38 | G39: Spectrum 83 | H39: 0.51 | I39: 12.83 | J39: 6.9 | K39: 45.87 | L39: 22.83 | M39: 2.22 | N39: 0 | O39: 0 | P39: 0.08 | Q39: 6.45 | S39: 0 | T39: 0 | U39: 0 | V39: 97.69 | W39: 7.2438261 | X39: 0.28047607 | Y39: 198.00579 | Z39: 138.08689 | AA39: 30.697465 | AB39: 5.6717211 | AC39: 11.364788 | AD39: 1.3105753 | AE39: 1.3785319 | AF39: 8.7421885 | AG39: 0.084399643 | AH39: 0.031449558 | AI39: 0.3243605 | AJ39: 0.46111703 | AK39: 2.6740846 | AL39: 1.762936 | AM39: 28.393711 | AN39: 9.8743493 | AO39: 1.113383 | AP39: 8.3576864 | AQ39: 132.02125 | AR39: 13777.589 | AS39: 2.2478569 | AT39: 1.3737704 | AU39: 3.6482194 | AV39: 0.80115845 | AW39: 1.7241578 | AX39: 0.95652664 | AY39: =M39*47.9*10000/(47.9+32)-AR39 -> -468.70329 | AZ39: =AY39*100/AR39 -> -3.4019252
A40: 19ТР-16 | C40: 84 | D40: 43.31 | E40: 11 | F40: 39 | G40: Spectrum 84 | H40: 0.55 | I40: 11.73 | J40: 9.33 | K40: 43.31 | L40: 23.48 | M40: 4.31 | N40: 0 | O40: 0 | P40: 0 | Q40: 7.09 | S40: 0 | T40: 0 | U40: 0 | V40: 99.8 | W40: 7.1731311 | X40: 0.78145581 | Y40: 392.28567 | Z40: 584.1168 | AA40: 110.08298 | AB40: 16.069075 | AC40: 35.870407 | AD40: 3.2731721 | AE40: 3.4678601 | AF40: 25.701862 | AG40: 0.38605476 | AH40: 0.036967743 | AI40: 1.5289264 | AJ40: 1.1242045 | AK40: 6.6414492 | AL40: 4.2093519 | AM40: 81.308319 | AN40: 35.30747 | AO40: 6.8335092 | AP40: 21.602805 | AQ40: 197.45519 | AR40: 25574.901 | AS40: 2.069459 | AT40: 0.58772486 | AU40: 11.181615 | AV40: 1.8154295 | AW40: 4.1105586 | AX40: 2.4290859 | AY40: =M40*47.9*10000/(47.9+32)-AR40 -> 263.52175 | AZ40: =AY40*100/AR40 -> 1.0303921
...

Sheet для графера
A1: # EPMA | B1: La | C1: Ce | D1: Pr | E1: Nd | F1: Sm | G1: Eu | H1: Gd | I1: Tb | J1: Dy | K1: Ho | L1: Er | M1: Tm | N1: Yb | O1: Lu
B2: 0.237 | C2: 0.612 | D2: 0.095 | E2: 0.467 | F2: 0.153 | G2: 0.058 | H2: 0.2055 | I2: 0.0374 | J2: 0.254 | K2: 0.0566 | L2: 0.1655 | M2: 0.0255 | N2: 0.17 | O2: 0.0254
A3: 15 | B3: 1034.0432 | C3: 1781.6996 | E3: 476.37131 | F3: 45.304599 | G3: 11.094916 | H3: 54.955625 | J3: 16.599864 | K3: 3.064566 | L3: 7.8238434 | N3: 3.5079491
A4: 16 | B4: 245.31857 | C4: 596.78776 | E4: 278.86423 | F4: 38.624637 | G4: 10.390675 | H4: 24.219737 | J4: 12.988554 | K4: 2.5745193 | L4: 4.9377903 | N4: 4.4451114
A5: 20 | B5: 73.50371 | C5: 233.62538 | E5: 175.72799 | F5: 40.419738 | G5: 11.377122 | H5: 33.449854 | J5: 20.632013 | K5: 3.7600849 | L5: 9.9458186 | N5: 5.9405549
A6: 21 | B6: 119.25221 | C6: 419.29094 | E6: 250.70072 | F6: 30.735235 | G6: 6.9827542 | H6: 17.747186 | J6: 9.577458 | K6: 1.7153426 | L6: 3.7546305 | N6: 1.4955916
A7: 26 | B7: 110.41768 | C7: 278.01964 | E7: 226.77415 | F7: 107.00869 | G7: 43.214541 | H7: 130.54156 | J7: 202.14862 | K7: 45.975457 | L7: 155.23532 | N7: 139.92229
A8: 27 | B8: 119.88284 | C8: 462.66892 | E8: 431.0176 | F8: 88.850839 | G8: 25.776979 | H8: 64.999971 | J8: 52.944556 | K8: 10.310295 | L8: 28.493281 | N8: 25.399656
A9: 28 | B9: 112.27071 | C9: 484.68148 | E9: 434.37781 | F9: 85.743796 | G9: 24.524151 | H9: 63.023772 | J9: 54.334172 | K9: 11.340021 | L9: 33.618613 | N9: 29.651319
A10: 32 | B10: 128.84464 | C10: 566.86529 | E10: 533.37701 | F10: 108.79519 | G10: 30.423668 | H10: 65.263657 | J10: 47.439473 | K10: 8.8715454 | L10: 21.436387 | N10: 17.344705
A11: 33 | B11: 177.5212 | C11: 785.60467 | E11: 651.27022 | F11: 124.46545 | G11: 32.414096 | H11: 68.982309 | J11: 69.634282 | K11: 14.196713 | L11: 41.910994 | N11: 36.235466
A12: 44 | B12: 66.154722 | C12: 168.53461 | E12: 86.468565 | F12: 11.092044 | G12: 2.9045034 | H12: 8.8532852 | J12: 5.5091964 | K12: 1.0660738 | L12: 2.7028238 | N12: 1.3616188
A13: 45 | B13: 79.83491 | C13: 152.16439 | E13: 68.285755 | F13: 8.9608948 | G13: 2.2695313 | H13: 5.8044676 | J13: 4.8853062 | K13: 0.99705084 | L13: 3.2737241 | N13: 2.2049916
A14: 15 | B14: 86.945288 | C14: 422.2581 | E14: 391.58211 | F14: 69.428906 | G14: 18.785499 | H14: 44.003416 | J14: 30.615247 | K14: 5.4273051 | L14: 12.017833 | N14: 7.4592621
... A26: 25 | B26: 39.873802 | C26: 172.23304 | E26: 288.42039 | F26: 204.58702 | G26: 94.672837 | H26: 366.66404 | J26: 618.74001 | K26: 140.11129 | L26: 500.36581 | N26: 528.36255
A28: 15 | B28: =B3/B$2 -> 4363.0515 | C28: =C3/C$2 -> 2911.2739 | E28: =E3/E$2 -> 1020.067 | F28: =F3/F$2 -> 296.10849 | G28: =G3/G$2 -> 191.29166 | H28: =H3/H$2 -> 267.42396 | J28: =J3/J$2 -> 65.353797 | K28: =K3/K$2 -> 54.144276 | L28: =L3/L$2 -> 47.273978 | N28: =N3/N$2 -> 20.634995
A29: 16 | B29: =B4/B$2 -> 1035.0994 | C29: =C4/C$2 -> 975.1434 | E29: =E4/E$2 -> 597.13968 | F29: =F4/F$2 -> 252.44861 | G29: =G4/G$2 -> 179.14957 | H29: =H4/H$2 -> 117.8576 | J29: =J4/J$2 -> 51.13604 | K29: =K4/K$2 -> 45.486207 | L29: =L4/L$2 -> 29.835591 | N29: =N4/N$2 -> 26.147714
A30: 20 | B30: =B5/B$2 -> 310.14224 | C30: =C5/C$2 -> 381.74082 | E30: =E5/E$2 -> 376.2912 | F30: =F5/F$2 -> 264.1813 | G30: =G5/G$2 -> 196.15728 | H30: =H5/H$2 -> 162.77301 | J30: =J5/J$2 -> 81.228399 | K30: =K5/K$2 -> 66.432595 | L30: =L5/L$2 -> 60.095581 | N30: =N5/N$2 -> 34.944441
